*** Starting uWSGI 2.0.23 (64bit) on [Mon Nov  4 02:41:47 2024] ***
compiled with version: 12.3.0 on 25 January 2024 19:56:29
os: Linux-5.15.0-1063-oracle #69~20.04.1-Ubuntu SMP Sat Jun 29 02:22:36 UTC 2024
nodename: mlb-vps
machine: aarch64
clock source: unix
pcre jit disabled
detected number of CPU cores: 2
current working directory: /home/ubuntu/stockApi
writing pidfile to uwsgi.pid
detected binary path: /home/ubuntu/miniconda3/envs/django/bin/uwsgi
chdir() to /home/ubuntu/stockApi
your processes number limit is 47244
your memory page size is 4096 bytes
detected max file descriptor number: 1024
building mime-types dictionary from file /etc/mime.types...567 entry found
lock engine: pthread robust mutexes
thunder lock: disabled (you can enable it with --thunder-lock)
uWSGI http bound on 0.0.0.0:8000 fd 4
uwsgi socket 0 bound to TCP address 127.0.0.1:37995 (port auto-assigned) fd 3
Python version: 3.12.1 | packaged by conda-forge | (main, Dec 23 2023, 13:38:26) [GCC 12.3.0]
Python main interpreter initialized at 0xaaaae56ae8a8
python threads support enabled
your server socket listen backlog is limited to 100 connections
your mercy for graceful operations on workers is 60 seconds
mapped 166752 bytes (162 KB) for 2 cores
*** Operational MODE: threaded ***
Traceback (most recent call last):
  File "/home/ubuntu/stockApi/stockApi/__init__.py", line 1, in <module>
    import pymysql
ModuleNotFoundError: No module named 'pymysql'
unable to load app 0 (mountpoint='') (callable not found or import error)
Traceback (most recent call last):
  File "stockApi/wsgi.py", line 16, in <module>
    application = get_wsgi_application()
                  ^^^^^^^^^^^^^^^^^^^^^^
  File "/home/ubuntu/miniconda3/envs/django/lib/python3.12/site-packages/django/core/wsgi.py", line 12, in get_wsgi_application
    django.setup(set_prefix=False)
  File "/home/ubuntu/miniconda3/envs/django/lib/python3.12/site-packages/django/__init__.py", line 19, in setup
    configure_logging(settings.LOGGING_CONFIG, settings.LOGGING)
                      ^^^^^^^^^^^^^^^^^^^^^^^
  File "/home/ubuntu/miniconda3/envs/django/lib/python3.12/site-packages/django/conf/__init__.py", line 92, in __getattr__
    self._setup(name)
  File "/home/ubuntu/miniconda3/envs/django/lib/python3.12/site-packages/django/conf/__init__.py", line 79, in _setup
    self._wrapped = Settings(settings_module)
                    ^^^^^^^^^^^^^^^^^^^^^^^^^
  File "/home/ubuntu/miniconda3/envs/django/lib/python3.12/site-packages/django/conf/__init__.py", line 190, in __init__
    mod = importlib.import_module(self.SETTINGS_MODULE)
          ^^^^^^^^^^^^^^^^^^^^^^^^^^^^^^^^^^^^^^^^^^^^^
  File "/home/ubuntu/miniconda3/envs/django/lib/python3.12/importlib/__init__.py", line 90, in import_module
    return _bootstrap._gcd_import(name[level:], package, level)
           ^^^^^^^^^^^^^^^^^^^^^^^^^^^^^^^^^^^^^^^^^^^^^^^^^^^^
  File "<frozen importlib._bootstrap>", line 1387, in _gcd_import
  File "<frozen importlib._bootstrap>", line 1360, in _find_and_load
  File "<frozen importlib._bootstrap>", line 1310, in _find_and_load_unlocked
  File "<frozen importlib._bootstrap>", line 488, in _call_with_frames_removed
  File "<frozen importlib._bootstrap>", line 1387, in _gcd_import
  File "<frozen importlib._bootstrap>", line 1360, in _find_and_load
  File "<frozen importlib._bootstrap>", line 1331, in _find_and_load_unlocked
  File "<frozen importlib._bootstrap>", line 935, in _load_unlocked
  File "<frozen importlib._bootstrap_external>", line 994, in exec_module
  File "<frozen importlib._bootstrap>", line 488, in _call_with_frames_removed
  File "/home/ubuntu/stockApi/stockApi/__init__.py", line 1, in <module>
    import pymysql
ModuleNotFoundError: No module named 'pymysql'
unable to load app 0 (mountpoint='') (callable not found or import error)
*** no app loaded. going in full dynamic mode ***
*** uWSGI is running in multiple interpreter mode ***
spawned uWSGI master process (pid: 2641396)
spawned uWSGI worker 1 (pid: 2641397, cores: 2)
spawned uWSGI http 1 (pid: 2641399)
Python auto-reloader enabled
--- no python application found, check your startup logs for errors ---
[pid: 2641397|app: -1|req: -1/1] 207.211.146.175 () {34 vars in 464 bytes} [Mon Nov  4 02:42:45 2024] GET /api/basics/basic/ => generated 21 bytes in 0 msecs (HTTP/1.1 500) 2 headers in 83 bytes (0 switches on core 0)
[uwsgi-python-reloader] module/file /home/ubuntu/miniconda3/envs/django/lib/python3.12/site-packages/asgiref/__init__.py has been modified
gateway "uWSGI http 1" has been buried (pid: 2641399)
...gracefully killing workers...
Gracefully killing worker 1 (pid: 2641397)...
worker 1 buried after 1 seconds
binary reloading uWSGI...
chdir() to /home/ubuntu/stockApi
closing all non-uwsgi socket fds > 2 (max_fd = 1024)...
found fd 3 mapped to socket 0 (127.0.0.1:37995)
running /home/ubuntu/miniconda3/envs/django/bin/uwsgi
[uWSGI] getting INI configuration from stockApiUwsgi.ini
[uwsgi-static] added mapping for /static => /home/ubuntu/stockApi/static
*** Starting uWSGI 2.0.23 (64bit) on [Mon Nov  4 02:45:30 2024] ***
compiled with version: 12.3.0 on 25 January 2024 19:56:29
os: Linux-5.15.0-1063-oracle #69~20.04.1-Ubuntu SMP Sat Jun 29 02:22:36 UTC 2024
nodename: mlb-vps
machine: aarch64
clock source: unix
pcre jit disabled
detected number of CPU cores: 2
current working directory: /home/ubuntu/stockApi
detected binary path: /home/ubuntu/miniconda3/envs/django/bin/uwsgi
chdir() to /home/ubuntu/stockApi
your processes number limit is 47244
your memory page size is 4096 bytes
detected max file descriptor number: 1024
building mime-types dictionary from file /etc/mime.types...567 entry found
lock engine: pthread robust mutexes
thunder lock: disabled (you can enable it with --thunder-lock)
uWSGI http bound on 0.0.0.0:8000 fd 5
uwsgi socket 0 bound to TCP address 127.0.0.1:35157 (port auto-assigned) fd 4
Python version: 3.12.1 | packaged by conda-forge | (main, Dec 23 2023, 13:38:26) [GCC 12.3.0]
Python main interpreter initialized at 0xaaaabf61e8a8
python threads support enabled
your server socket listen backlog is limited to 100 connections
your mercy for graceful operations on workers is 60 seconds
mapped 166752 bytes (162 KB) for 2 cores
*** Operational MODE: threaded ***
Traceback (most recent call last):
  File "/home/ubuntu/stockApi/stockApi/wsgi.py", line 16, in <module>
    application = get_wsgi_application()
                  ^^^^^^^^^^^^^^^^^^^^^^
  File "/home/ubuntu/miniconda3/envs/django/lib/python3.12/site-packages/django/core/wsgi.py", line 12, in get_wsgi_application
    django.setup(set_prefix=False)
  File "/home/ubuntu/miniconda3/envs/django/lib/python3.12/site-packages/django/__init__.py", line 24, in setup
    apps.populate(settings.INSTALLED_APPS)
  File "/home/ubuntu/miniconda3/envs/django/lib/python3.12/site-packages/django/apps/registry.py", line 91, in populate
    app_config = AppConfig.create(entry)
                 ^^^^^^^^^^^^^^^^^^^^^^^
  File "/home/ubuntu/miniconda3/envs/django/lib/python3.12/site-packages/django/apps/config.py", line 193, in create
    import_module(entry)
  File "/home/ubuntu/miniconda3/envs/django/lib/python3.12/importlib/__init__.py", line 90, in import_module
    return _bootstrap._gcd_import(name[level:], package, level)
           ^^^^^^^^^^^^^^^^^^^^^^^^^^^^^^^^^^^^^^^^^^^^^^^^^^^^
ModuleNotFoundError: No module named 'rest_framework_simplejwt'
unable to load app 0 (mountpoint='') (callable not found or import error)
Traceback (most recent call last):
  File "stockApi/wsgi.py", line 16, in <module>
    application = get_wsgi_application()
                  ^^^^^^^^^^^^^^^^^^^^^^
  File "/home/ubuntu/miniconda3/envs/django/lib/python3.12/site-packages/django/core/wsgi.py", line 12, in get_wsgi_application
    django.setup(set_prefix=False)
  File "/home/ubuntu/miniconda3/envs/django/lib/python3.12/site-packages/django/__init__.py", line 24, in setup
    apps.populate(settings.INSTALLED_APPS)
  File "/home/ubuntu/miniconda3/envs/django/lib/python3.12/site-packages/django/apps/registry.py", line 83, in populate
    raise RuntimeError("populate() isn't reentrant")
RuntimeError: populate() isn't reentrant
unable to load app 0 (mountpoint='') (callable not found or import error)
*** no app loaded. going in full dynamic mode ***
*** uWSGI is running in multiple interpreter mode ***
gracefully (RE)spawned uWSGI master process (pid: 2641396)
spawned uWSGI worker 1 (pid: 2642320, cores: 2)
spawned uWSGI http 1 (pid: 2642321)
Python auto-reloader enabled
--- no python application found, check your startup logs for errors ---
[pid: 2642320|app: -1|req: -1/1] 207.211.146.175 () {34 vars in 465 bytes} [Mon Nov  4 10:48:12 2024] GET /api/basics/basic/ => generated 21 bytes in 0 msecs (HTTP/1.1 500) 2 headers in 83 bytes (0 switches on core 0)
Mon Nov  4 10:49:35 2024 - uWSGI worker 1 screams: UAAAAAAH my master disconnected: i will kill myself !!!
Mon Nov  4 10:49:35 2024 - uWSGI worker 1 screams: UAAAAAAH my master disconnected: i will kill myself !!!
*** Starting uWSGI 2.0.21 (64bit) on [Mon Nov  4 03:11:25 2024] ***
compiled with version: 11.2.0 on 05 August 2024 19:33:33
os: Linux-5.15.0-1063-oracle #69~20.04.1-Ubuntu SMP Sat Jun 29 02:22:36 UTC 2024
nodename: mlb-vps
machine: aarch64
clock source: unix
pcre jit disabled
detected number of CPU cores: 2
current working directory: /home/ubuntu/stockApi
writing pidfile to uwsgi.pid
detected binary path: /home/ubuntu/miniconda3/envs/django/bin/uwsgi
chdir() to /home/ubuntu/stockApi
your processes number limit is 47244
your memory page size is 4096 bytes
detected max file descriptor number: 1024
building mime-types dictionary from file /etc/mime.types...567 entry found
lock engine: pthread robust mutexes
thunder lock: disabled (you can enable it with --thunder-lock)
uWSGI http bound on 0.0.0.0:8000 fd 4
uwsgi socket 0 bound to TCP address 127.0.0.1:37277 (port auto-assigned) fd 3
Python version: 3.9.19 (main, May  6 2024, 19:46:57)  [GCC 11.2.0]
Python main interpreter initialized at 0x2251c5a0
python threads support enabled
your server socket listen backlog is limited to 100 connections
your mercy for graceful operations on workers is 60 seconds
mapped 166752 bytes (162 KB) for 2 cores
*** Operational MODE: threaded ***
WSGI app 0 (mountpoint='') ready in 1 seconds on interpreter 0x2251c5a0 pid: 2649133 (default app)
mountpoint  already configured. skip.
*** uWSGI is running in multiple interpreter mode ***
spawned uWSGI master process (pid: 2649133)
spawned uWSGI worker 1 (pid: 2649134, cores: 2)
Python auto-reloader enabled
spawned uWSGI http 1 (pid: 2649137)
Internal Server Error: /api/basics/basic/
Traceback (most recent call last):
  File "/home/ubuntu/miniconda3/envs/django/lib/python3.9/site-packages/pymysql/connections.py", line 732, in _read_bytes
    data = self._rfile.read(num_bytes)
  File "/home/ubuntu/miniconda3/envs/django/lib/python3.9/socket.py", line 716, in readinto
    return self._sock.recv_into(b)
socket.timeout: timed out

During handling of the above exception, another exception occurred:

Traceback (most recent call last):
  File "/home/ubuntu/miniconda3/envs/django/lib/python3.9/site-packages/django/db/backends/utils.py", line 89, in _execute
    return self.cursor.execute(sql, params)
  File "/home/ubuntu/miniconda3/envs/django/lib/python3.9/site-packages/django/db/backends/mysql/base.py", line 75, in execute
    return self.cursor.execute(query, args)
  File "/home/ubuntu/miniconda3/envs/django/lib/python3.9/site-packages/pymysql/cursors.py", line 148, in execute
    result = self._query(query)
  File "/home/ubuntu/miniconda3/envs/django/lib/python3.9/site-packages/pymysql/cursors.py", line 310, in _query
    conn.query(q)
  File "/home/ubuntu/miniconda3/envs/django/lib/python3.9/site-packages/pymysql/connections.py", line 548, in query
    self._affected_rows = self._read_query_result(unbuffered=unbuffered)
  File "/home/ubuntu/miniconda3/envs/django/lib/python3.9/site-packages/pymysql/connections.py", line 775, in _read_query_result
    result.read()
  File "/home/ubuntu/miniconda3/envs/django/lib/python3.9/site-packages/pymysql/connections.py", line 1156, in read
    first_packet = self.connection._read_packet()
  File "/home/ubuntu/miniconda3/envs/django/lib/python3.9/site-packages/pymysql/connections.py", line 692, in _read_packet
    packet_header = self._read_bytes(4)
  File "/home/ubuntu/miniconda3/envs/django/lib/python3.9/site-packages/pymysql/connections.py", line 738, in _read_bytes
    raise err.OperationalError(
pymysql.err.OperationalError: (2013, 'Lost connection to MySQL server during query (timed out)')

The above exception was the direct cause of the following exception:

Traceback (most recent call last):
  File "/home/ubuntu/miniconda3/envs/django/lib/python3.9/site-packages/django/core/handlers/exception.py", line 55, in inner
    response = get_response(request)
  File "/home/ubuntu/miniconda3/envs/django/lib/python3.9/site-packages/django/core/handlers/base.py", line 197, in _get_response
    response = wrapped_callback(request, *callback_args, **callback_kwargs)
  File "/home/ubuntu/miniconda3/envs/django/lib/python3.9/site-packages/django/views/decorators/csrf.py", line 56, in wrapper_view
    return view_func(*args, **kwargs)
  File "/home/ubuntu/miniconda3/envs/django/lib/python3.9/site-packages/rest_framework/viewsets.py", line 124, in view
    return self.dispatch(request, *args, **kwargs)
  File "/home/ubuntu/miniconda3/envs/django/lib/python3.9/site-packages/rest_framework/views.py", line 509, in dispatch
    response = self.handle_exception(exc)
  File "/home/ubuntu/miniconda3/envs/django/lib/python3.9/site-packages/rest_framework/views.py", line 469, in handle_exception
    self.raise_uncaught_exception(exc)
  File "/home/ubuntu/miniconda3/envs/django/lib/python3.9/site-packages/rest_framework/views.py", line 480, in raise_uncaught_exception
    raise exc
  File "/home/ubuntu/miniconda3/envs/django/lib/python3.9/site-packages/rest_framework/views.py", line 506, in dispatch
    response = handler(request, *args, **kwargs)
  File "/home/ubuntu/miniconda3/envs/django/lib/python3.9/site-packages/rest_framework/mixins.py", line 46, in list
    return Response(serializer.data)
  File "/home/ubuntu/miniconda3/envs/django/lib/python3.9/site-packages/rest_framework/serializers.py", line 795, in data
    ret = super().data
  File "/home/ubuntu/miniconda3/envs/django/lib/python3.9/site-packages/rest_framework/serializers.py", line 249, in data
    self._data = self.to_representation(self.instance)
  File "/home/ubuntu/miniconda3/envs/django/lib/python3.9/site-packages/rest_framework/serializers.py", line 713, in to_representation
    return [
  File "/home/ubuntu/miniconda3/envs/django/lib/python3.9/site-packages/django/db/models/query.py", line 398, in __iter__
    self._fetch_all()
  File "/home/ubuntu/miniconda3/envs/django/lib/python3.9/site-packages/django/db/models/query.py", line 1881, in _fetch_all
    self._result_cache = list(self._iterable_class(self))
  File "/home/ubuntu/miniconda3/envs/django/lib/python3.9/site-packages/django/db/models/query.py", line 91, in __iter__
    results = compiler.execute_sql(
  File "/home/ubuntu/miniconda3/envs/django/lib/python3.9/site-packages/django/db/models/sql/compiler.py", line 1562, in execute_sql
    cursor.execute(sql, params)
  File "/home/ubuntu/miniconda3/envs/django/lib/python3.9/site-packages/django/db/backends/utils.py", line 102, in execute
    return super().execute(sql, params)
  File "/home/ubuntu/miniconda3/envs/django/lib/python3.9/site-packages/django/db/backends/utils.py", line 67, in execute
    return self._execute_with_wrappers(
  File "/home/ubuntu/miniconda3/envs/django/lib/python3.9/site-packages/django/db/backends/utils.py", line 80, in _execute_with_wrappers
    return executor(sql, params, many, context)
  File "/home/ubuntu/miniconda3/envs/django/lib/python3.9/site-packages/django/db/backends/utils.py", line 89, in _execute
    return self.cursor.execute(sql, params)
  File "/home/ubuntu/miniconda3/envs/django/lib/python3.9/site-packages/django/db/utils.py", line 91, in __exit__
    raise dj_exc_value.with_traceback(traceback) from exc_value
  File "/home/ubuntu/miniconda3/envs/django/lib/python3.9/site-packages/django/db/backends/utils.py", line 89, in _execute
    return self.cursor.execute(sql, params)
  File "/home/ubuntu/miniconda3/envs/django/lib/python3.9/site-packages/django/db/backends/mysql/base.py", line 75, in execute
    return self.cursor.execute(query, args)
  File "/home/ubuntu/miniconda3/envs/django/lib/python3.9/site-packages/pymysql/cursors.py", line 148, in execute
    result = self._query(query)
  File "/home/ubuntu/miniconda3/envs/django/lib/python3.9/site-packages/pymysql/cursors.py", line 310, in _query
    conn.query(q)
  File "/home/ubuntu/miniconda3/envs/django/lib/python3.9/site-packages/pymysql/connections.py", line 548, in query
    self._affected_rows = self._read_query_result(unbuffered=unbuffered)
  File "/home/ubuntu/miniconda3/envs/django/lib/python3.9/site-packages/pymysql/connections.py", line 775, in _read_query_result
    result.read()
  File "/home/ubuntu/miniconda3/envs/django/lib/python3.9/site-packages/pymysql/connections.py", line 1156, in read
    first_packet = self.connection._read_packet()
  File "/home/ubuntu/miniconda3/envs/django/lib/python3.9/site-packages/pymysql/connections.py", line 692, in _read_packet
    packet_header = self._read_bytes(4)
  File "/home/ubuntu/miniconda3/envs/django/lib/python3.9/site-packages/pymysql/connections.py", line 738, in _read_bytes
    raise err.OperationalError(
django.db.utils.OperationalError: (2013, 'Lost connection to MySQL server during query (timed out)')
[pid: 2649134|app: 0|req: 1/1] 207.211.146.175 () {34 vars in 465 bytes} [Mon Nov  4 11:11:38 2024] GET /api/basics/basic/ => generated 223558 bytes in 60620 msecs (HTTP/1.1 500) 7 headers in 251 bytes (1 switches on core 0)
Bad Request: /api/basics/tushare/basic/
[pid: 2649134|app: 0|req: 2/2] 207.211.146.175 () {36 vars in 501 bytes} [Mon Nov  4 11:13:42 2024] POST /api/basics/tushare/basic/ => generated 125 bytes in 62995 msecs (HTTP/1.1 400) 8 headers in 265 bytes (1 switches on core 1)
Mon Nov  4 11:20:11 2024 - uWSGI worker 1 screams: UAAAAAAH my master disconnected: i will kill myself !!!
Mon Nov  4 11:20:11 2024 - uWSGI worker 1 screams: UAAAAAAH my master disconnected: i will kill myself !!!
*** Starting uWSGI 2.0.21 (64bit) on [Mon Nov  4 03:31:52 2024] ***
compiled with version: 11.2.0 on 05 August 2024 19:33:33
os: Linux-5.15.0-1063-oracle #69~20.04.1-Ubuntu SMP Sat Jun 29 02:22:36 UTC 2024
nodename: mlb-vps
machine: aarch64
clock source: unix
pcre jit disabled
detected number of CPU cores: 2
current working directory: /home/ubuntu/stockApi
writing pidfile to uwsgi.pid           # 将pid文件放在/tmp目录下
open("uwsgi.pid           # 将pid文件放在/tmp目录下"): No such file or directory [core/utils.c line 3624]
*** Starting uWSGI 2.0.21 (64bit) on [Mon Nov  4 03:33:31 2024] ***
compiled with version: 11.2.0 on 05 August 2024 19:33:33
os: Linux-5.15.0-1063-oracle #69~20.04.1-Ubuntu SMP Sat Jun 29 02:22:36 UTC 2024
nodename: mlb-vps
machine: aarch64
clock source: unix
pcre jit disabled
detected number of CPU cores: 2
current working directory: /home/ubuntu/stockApi
writing pidfile to /home/ubuntu/stockApi/uwsgi.pid           # 将pid文件放在/tmp目录下
open("/home/ubuntu/stockApi/uwsgi.pid           # 将pid文件放在/tmp目录下"): No such file or directory [core/utils.c line 3624]
*** Starting uWSGI 2.0.21 (64bit) on [Mon Nov  4 03:35:10 2024] ***
compiled with version: 11.2.0 on 05 August 2024 19:33:33
os: Linux-5.15.0-1063-oracle #69~20.04.1-Ubuntu SMP Sat Jun 29 02:22:36 UTC 2024
nodename: mlb-vps
machine: aarch64
clock source: unix
pcre jit disabled
detected number of CPU cores: 2
current working directory: /home/ubuntu/stockApi
writing pidfile to /home/ubuntu/stockApi/uwsgi.pid
detected binary path: /home/ubuntu/miniconda3/envs/django/bin/uwsgi
chdir() to /home/ubuntu/stockApi
your processes number limit is 47244
your memory page size is 4096 bytes
 *** WARNING: you have enabled harakiri without post buffering. Slow upload could be rejected on post-unbuffered webservers *** 
detected max file descriptor number: 1024
building mime-types dictionary from file /etc/mime.types...567 entry found
lock engine: pthread robust mutexes
thunder lock: enabled
uWSGI http bound on 0.0.0.0:8000 fd 7
uwsgi socket 0 bound to TCP address 127.0.0.1:35137 (port auto-assigned) fd 6
Python version: 3.9.19 (main, May  6 2024, 19:46:57)  [GCC 11.2.0]
Python main interpreter initialized at 0x21b27b00
python threads support enabled
your server socket listen backlog is limited to 100 connections
your mercy for graceful operations on workers is 60 seconds
mapped 703600 bytes (687 KB) for 8 cores
*** Operational MODE: preforking+threaded ***
*** uWSGI is running in multiple interpreter mode ***
spawned uWSGI master process (pid: 2655052)
spawned uWSGI worker 1 (pid: 2655053, cores: 2)
spawned uWSGI worker 2 (pid: 2655054, cores: 2)
spawned uWSGI worker 3 (pid: 2655055, cores: 2)
spawned uWSGI worker 4 (pid: 2655056, cores: 2)
spawned uWSGI http 1 (pid: 2655057)
Python auto-reloader enabled
WSGI app 0 (mountpoint='') ready in 0 seconds on interpreter 0x21b27b00 pid: 2655054 (default app)
mountpoint  already configured. skip.
WSGI app 0 (mountpoint='') ready in 0 seconds on interpreter 0x21b27b00 pid: 2655053 (default app)
mountpoint  already configured. skip.
WSGI app 0 (mountpoint='') ready in 1 seconds on interpreter 0x21b27b00 pid: 2655056 (default app)
mountpoint  already configured. skip.
WSGI app 0 (mountpoint='') ready in 1 seconds on interpreter 0x21b27b00 pid: 2655055 (default app)
mountpoint  already configured. skip.
[pid: 2655054|app: 0|req: 1/1] 207.211.146.175 () {34 vars in 465 bytes} [Mon Nov  4 11:35:33 2024] GET /api/basics/basic/ => generated 2 bytes in 543 msecs (HTTP/1.1 200) 8 headers in 254 bytes (1 switches on core 0)
开始将数据进行转换
开始插入数据
Bad Request: /api/basics/tushare/basic/
[pid: 2655054|app: 0|req: 2/2] 207.211.146.175 () {36 vars in 501 bytes} [Mon Nov  4 11:35:39 2024] POST /api/basics/tushare/basic/ => generated 103 bytes in 3675 msecs (HTTP/1.1 400) 8 headers in 265 bytes (1 switches on core 1)
Not Found: /
[pid: 2655053|app: 0|req: 1/3] 125.230.169.50 () {28 vars in 423 bytes} [Mon Nov  4 11:42:46 2024] GET / => generated 2277 bytes in 508 msecs (HTTP/1.0 404) 7 headers in 229 bytes (1 switches on core 0)
Not Found: /
[pid: 2655053|app: 0|req: 2/4] 198.235.24.147 () {28 vars in 565 bytes} [Mon Nov  4 12:35:40 2024] GET / => generated 2285 bytes in 43 msecs (HTTP/1.1 404) 7 headers in 229 bytes (1 switches on core 1)
